I'm sorry, but an uncaught exception occurred.

While running game code:
  File "game/script.rpy", line 58, in script call
    call ch1 from _call_ch1
  File "game/chapters/chap1/ch1.rpy", line 77, in script call
    call ch1_1
  File "game/chapters/chap1/ch1_1.rpy", line 37, in script call
    call ch1_1_2
  File "game/chapters/chap1/ch1_1_2.rpy", line 17, in script
    m1 "¡Aah! ¡Suelta mi monedero!"
Exception: Sayer 'm1' is not defined.

-- Full Traceback ------------------------------------------------------------

Full traceback:
  File "game/script.rpy", line 58, in script call
    call ch1 from _call_ch1
  File "game/chapters/chap1/ch1.rpy", line 77, in script call
    call ch1_1
  File "game/chapters/chap1/ch1_1.rpy", line 37, in script call
    call ch1_1_2
  File "game/chapters/chap1/ch1_1_2.rpy", line 17, in script
    m1 "¡Aah! ¡Suelta mi monedero!"
  File "C:\Users\alexa\Desktop\renpy-6.99.11-sdk\renpy\ast.py", line 583, in execute
    who = eval_who(self.who, self.who_fast)
  File "C:\Users\alexa\Desktop\renpy-6.99.11-sdk\renpy\ast.py", line 500, in eval_who
    raise Exception("Sayer '%s' is not defined." % who.encode("utf-8"))
Exception: Sayer 'm1' is not defined.

Windows-8-6.2.9200
Ren'Py 6.99.11.1749
MomotaroAdventure 1.0
